<?xml version="1.0" encoding="UTF-8"?>
<robot name="vs050">

	<link name="world"/>

	<joint name="joint_w" type="fixed">
		<parent link="world"/>
		<child link="base_link"/>
	</joint>

	<link name="base_link">
		<!-- <visual>
			<origin rpy="0 0 0" xyz="0 0 0"/>
		</visual> -->
		<!-- <collision>
			<origin rpy="0 0 0" xyz="0 0 0"/>
		</collision> -->
		<inertial>
			<mass value="1"/>
			<origin rpy="0.000000 0.000000 0.000000" xyz="0.000000 0.000000 0.000000"/>
			<inertia ixx="1" ixy="0" ixz="0" iyy="1" iyz="0" izz="1"/>
		</inertial>
	</link>

	<link name="J1">
		<!-- <visual>
			<origin rpy="0 0 0" xyz="0 0 0"/>
		</visual>
		<collision>
			<origin rpy="0 0 0" xyz="0 0 0"/>
		</collision> -->
		<inertial>
			<mass value="1"/>
			<origin rpy="0.000000 0.000000 0.000000" xyz="0.000000 0.000000 0.000000"/>
			<inertia ixx="1" ixy="0" ixz="0" iyy="1" iyz="0" izz="1"/>
		</inertial>
	</link>

	<joint name="joint_1" type="revolute">
		<parent link="base_link"/>
		<child link="J1"/>
		<origin rpy="0.000000 0.000000 0.000000" xyz="0.000000 0.000000 0.000000"/>
		<axis xyz="-0.000000 -0.000000 1.000000"/>
		<!-- <limit effort="1" lower="-2.967059728" upper="2.967059728" velocity="4"/> -->
		<limit effort="1" lower="-1.570796" upper="1.570796" velocity="4"/>
		<dynamics damping="0" friction="0"/>
	</joint>
	<transmission name="trans_1">
		<type>transmission_interface/SimpleTransmission</type>
		<joint name="joint_1">
			<hardwareInterface>PositionJointInterface</hardwareInterface>
		</joint>
		<actuator name="motor_1">
			<hardwareInterface>PositionJointInterface</hardwareInterface>
			<mechanicalReduction>1</mechanicalReduction>
		</actuator>
	</transmission>

	<link name="J2">
		<!-- <visual>
			<origin rpy="0 0 0" xyz="0 0 0"/>
		</visual>
		<collision>
			<origin rpy="0 0 0" xyz="0 0 0"/>
		</collision> -->
		<inertial>
			<mass value="1"/>
			<origin rpy="0.000000 0.000000 0.000000" xyz="0.000000 0.000000 0.000000"/>
			<inertia ixx="1" ixy="0" ixz="0" iyy="1" iyz="0" izz="1"/>
		</inertial>
	</link>

	<joint name="joint_2" type="revolute">
		<parent link="J1"/>
		<child link="J2"/>
		<origin rpy="0.000000 0.000000 0.000000" xyz="0.000000 0.000000 0.345000"/>
		<axis xyz="-0.000000 1.000000 -0.000000"/>
		<!-- <limit effort="1" lower="-2.094395102" upper="2.094395102" velocity="4"/> -->
		<limit effort="1" lower="-0.087266" upper="1.570796" velocity="4"/>
		<dynamics damping="0" friction="0"/>
	</joint>
	<transmission name="trans_2">
		<type>transmission_interface/SimpleTransmission</type>
		<joint name="joint_2">
			<hardwareInterface>PositionJointInterface</hardwareInterface>
		</joint>
		<actuator name="motor_2">
			<hardwareInterface>PositionJointInterface</hardwareInterface>
			<mechanicalReduction>1</mechanicalReduction>
		</actuator>
	</transmission>

	<link name="J3">
		<!-- <visual>
			<origin rpy="0 0 0" xyz="0 0 0"/>
		</visual>
		<collision>
			<origin rpy="0 0 0" xyz="0 0 0"/>
		</collision> -->
		<inertial>
			<mass value="1"/>
			<origin rpy="0.000000 0.000000 0.000000" xyz="0.000000 0.000000 0.000000"/>
			<inertia ixx="1" ixy="0" ixz="0" iyy="1" iyz="0" izz="1"/>
		</inertial>
	</link>

	<joint name="joint_3" type="revolute">
		<parent link="J2"/>
		<child link="J3"/>
		<origin rpy="0.000000 0.000000 0.000000" xyz="0.000000 0.000000 0.250000"/>
		<axis xyz="-0.000000 1.000000 -0.000000"/>
		<!-- <limit effort="1" lower="-2.094395102" upper="2.635447171" velocity="4"/> -->
		<limit effort="1" lower="0" upper="2.1642" velocity="4"/>
		<dynamics damping="0" friction="0"/>
	</joint>
	<transmission name="trans_3">
		<type>transmission_interface/SimpleTransmission</type>
		<joint name="joint_3">
			<hardwareInterface>PositionJointInterface</hardwareInterface>
		</joint>
		<actuator name="motor_3">
			<hardwareInterface>PositionJointInterface</hardwareInterface>
			<mechanicalReduction>1</mechanicalReduction>
		</actuator>
	</transmission>

	<link name="J4">
		<!-- <visual>
			<origin rpy="0 0 0" xyz="0 0 0"/>
		</visual>
		<collision>
			<origin rpy="0 0 0" xyz="0 0 0"/>
		</collision> -->
		<inertial>
			<mass value="1"/>
			<origin rpy="0.000000 0.000000 0.000000" xyz="0.000000 0.000000 0.000000"/>
			<inertia ixx="1" ixy="0" ixz="0" iyy="1" iyz="0" izz="1"/>
		</inertial>
	</link>

	<joint name="joint_4" type="revolute">
		<parent link="J3"/>
		<child link="J4"/>
		<origin rpy="0.000000 0.000000 0.000000" xyz="-0.010000 0.000000 -0.595000"/>
		<axis xyz="-0.000000 -0.000000 1.000000"/>
		<!-- <limit effort="1" lower="-4.712389" upper="4.712389" velocity="4"/> -->
		<limit effort="1" lower="0.0" upper="3.1416" velocity="4"/>
		<dynamics damping="0" friction="0"/>
	</joint>
	<transmission name="trans_4">
		<type>transmission_interface/SimpleTransmission</type>
		<joint name="joint_4">
			<hardwareInterface>PositionJointInterface</hardwareInterface>
		</joint>
		<actuator name="motor_4">
			<hardwareInterface>PositionJointInterface</hardwareInterface>
			<mechanicalReduction>1</mechanicalReduction>
		</actuator>
	</transmission>

	<link name="J5">
		<!-- <visual>
			<origin rpy="0 0 0" xyz="0 0 0"/>
		</visual>
		<collision>
			<origin rpy="0 0 0" xyz="0 0 0"/>
		</collision> -->
		<inertial>
			<mass value="1"/>
			<origin rpy="0.000000 0.000000 0.000000" xyz="0.000000 0.000000 0.000000"/>
			<inertia ixx="1" ixy="0" ixz="0" iyy="1" iyz="0" izz="1"/>
		</inertial>
	</link>

	<joint name="joint_5" type="revolute">
		<parent link="J4"/>
		<child link="J5"/>
		<origin rpy="0.000000 0.000000 0.000000" xyz="0.000000 0.000000 0.850000"/>
		<axis xyz="-0.000000 1.000000 -0.000000"/>
		<!-- <limit effort="1" lower="-2.094395102" upper="2.094395102" velocity="4"/> -->
		<limit effort="1" lower="-1.570796" upper="1.570796" velocity="4"/>
		<dynamics damping="0" friction="0"/>
	</joint>
	<transmission name="trans_5">
		<type>transmission_interface/SimpleTransmission</type>
		<joint name="joint_5">
			<hardwareInterface>PositionJointInterface</hardwareInterface>
		</joint>
		<actuator name="motor_5">
			<hardwareInterface>PositionJointInterface</hardwareInterface>
			<mechanicalReduction>1</mechanicalReduction>
		</actuator>
	</transmission>

	<link name="J6">
		<!-- <visual>
			<origin rpy="0 0 0" xyz="0 0 0"/>
		</visual>
		<collision>
			<origin rpy="0 0 0" xyz="0 0 0"/>
		</collision> -->
		<inertial>
			<mass value="1"/>
			<origin rpy="0.000000 0.000000 0.000000" xyz="0.000000 0.000000 0.000000"/>
			<inertia ixx="1" ixy="0" ixz="0" iyy="1" iyz="0" izz="1"/>
		</inertial>
	</link>

	<joint name="joint_6" type="revolute">
		<parent link="J5"/>
		<child link="J6"/>
		<origin rpy="0.000000 0.000000 0.000000" xyz="0.000000 0.000000 0.070000"/>
		<axis xyz="-0.000000 -0.000000 1.000000"/>
		<!-- <limit effort="1" lower="-6.283185" upper="6.283185" velocity="4"/> -->
		<limit effort="1" lower="-3.141592654" upper="3.141592654" velocity="4"/>
		<dynamics damping="0" friction="0"/>
	</joint>
	<transmission name="trans_6">
		<type>transmission_interface/SimpleTransmission</type>
		<joint name="joint_6">
			<hardwareInterface>PositionJointInterface</hardwareInterface>
		</joint>
		<actuator name="motor_6">
			<hardwareInterface>PositionJointInterface</hardwareInterface>
			<mechanicalReduction>1</mechanicalReduction>
		</actuator>
	</transmission>

</robot>
